<?xml version="1.0"?>
<robot name="Line_Follower">

    <material name="Grey">
        <color rgba="0.7 0.7 0.7 1" />
    </material>

    <material name="Green">
        <color rgba="0 0.5 0 1" />
    </material>

    <link name="base_footprint" />

    <link name="base_link">
        <visual>
            <geometry>
                <box size="0.6 0.4 0.1" />
            </geometry>
            <origin xyz="0 0 0.05" rpy="0 0 0" />    
            <material name="Green" />
        </visual>
        <collision>
            <origin xyz="0 0 0.05" rpy="0 0 0"/>
            <geometry>
                <box size="0.6 0.4 0.1"/>
            </geometry>
        </collision>
        <inertial>
            <origin xyz="0 0 0.05" rpy="0 0 0"/>
            <mass value="2.0"/>
            <inertia ixx="0.02" ixy="0.0" ixz="0.0" iyy="0.02" iyz="0.0" izz="0.02"/>
        </inertial>
    </link>

    <link name="Right_Wheel">
        <visual>
            <geometry>
                <cylinder length="0.025" radius="0.05" />
            </geometry>
            <origin xyz="0 0 0" rpy="0 0 0" />
            <material name="Grey" />
        </visual>
        <collision>
            <origin xyz="0 0 0" rpy="1.57 0 0"/>
            <geometry>
                <cylinder radius="0.05" length="0.05"/>
            </geometry>
        </collision>
        <inertial>
            <origin xyz="0 0 0" rpy="1.57 0 0"/>
            <mass value="0.2"/>
            <inertia ixx="0.001" ixy="0.0" ixz="0.0" iyy="0.001" iyz="0.0" izz="0.001"/>
        </inertial>
    </link>

    <link name="Left_Wheel">
        <visual>
            <geometry>
                <cylinder length="0.025" radius="0.05" />
            </geometry>
            <origin xyz="0 0 0" rpy="0 0 0" />
            <material name="Grey" />
        </visual>
        <collision>
            <origin xyz="0 0 0" rpy="1.57 0 0"/>
            <geometry>
                <cylinder radius="0.025" length="0.05"/>
            </geometry>
        </collision>
        <inertial>
            <origin xyz="0 0 0" rpy="1.57 0 0"/>
            <mass value="0.2"/>
            <inertia ixx="0.001" ixy="0.0" ixz="0.0" iyy="0.001" iyz="0.0" izz="0.001"/>
        </inertial>
    </link>
    
    <link name="castor_wheel">
        <visual>
            <geometry>
                <sphere radius="0.025" />
            </geometry>
            <material name="Grey" />
        </visual>
        <collision>
            <origin xyz="0 0 0" rpy="0 0 0"/>
            <geometry>
                <sphere radius="0.05"/>
            </geometry>
        </collision>
        <inertial>
            <origin xyz="0 0 0" rpy="0 0 0"/>
            <mass value="0.05"/>
            <inertia ixx="0.0001" ixy="0.0" ixz="0.0" iyy="0.0001" iyz="0.0" izz="0.0001"/>
        </inertial>
    </link>

    <joint name="base_joint" type="fixed">
        <parent link="base_footprint" />
        <child link="base_link" />
        <origin xyz = "0 0 0.025" rpy="0 0 0" />
    </joint>

    <joint name="Base_to_Right_Wheel" type="continuous">
        <parent link="base_link" />
        <child link="Right_Wheel" />
        <origin xyz="-0.15 0.2125 0" rpy="1.57 0 0" />
        <axis xyz="0 1 0" />
    </joint>

    <joint name="Base_to_left_Wheel" type="continuous">
        <parent link="base_link" />
        <child link="Left_Wheel" />
        <origin xyz="-0.15 -0.2125 0" rpy="1.57 0 0" />
        <axis xyz="0 1 0" />
    </joint>

    <joint name="base_castor_wheel_joint" type="fixed">
        <parent link="base_link" />
        <child link="castor_wheel" />
        <origin xyz="0.2 0 -0.025" rpy="0 0 0" />
    </joint>


</robot>
